Workbook

Sheet How to Fill
A1: RX Attribute List — How to Read & Fill
A2: Each attribute describes an observable behavior of the RX module. Every attribute is broken into test cases (one row each). The AL is written from the spec BEFORE the Verification Plan and the environment exist; Implemented / Checked are updated with V or X later, as verification progresses (the Summary sheet updates automatically).
A4: Column | B4: Meaning
A5: ID | B5: Unique attribute ID (group prefix + number). Referenced from the VP and from test logs.
A6: Group | B6: Logical grouping of attributes (by feature, lane, attribute type, …).
A7: Attribute (The module shall … when …) | B7: What the module does, written as an observable behavior triggered by a stimulus: "The module shall … when …".
A8: Notes / Assumptions | B8: Constraints, parameters, and assumptions the attribute depends on.
A9: Test Case (standard & corner cases) | B9: The concrete scenarios that must be exercised — standard cases and corner cases. One row per case.
A10: Priority | B10: High / Medium / Low — trade-off between importance and development time.
A11: Implemented (V / X) | B11: V = the scenario is implemented in the verification environment (stimulus + checker). X = not yet.
A12: Checked (V / X) | B12: V = the scenario was actually hit and measured by functional coverage. X = not yet. (Both status columns stay X when the AL is first written — they are filled in later, during verification.)
A14: Key parameters (from the block specification)
A15: • Input bus: 4 bits (nibble) + valid. Output bus: 32 bits.
A16: • LENGTH: 16 bits, protected by LENGTH_CRC (CRC-16, poly 0x1021, init 0xFFFF).
A17: • CONTROL: 16 bits, protected by CONTROL_CRC (CRC-16, poly 0x8005, init 0x0000).
A18: • PARITY: 32 bits at the end of each packet.
A19: • Payload length: 4 B (min) … 4096 B (optimal) … 8192 B (max).
A20: • Lock Valid Threshold (LVT): 2 (min) … 7 (optimal) … 12 (max).
A22: Lock state machine
A23: • NOT_LOCKED — searching every phase for a valid (LENGTH, LENGTH_CRC) pair.
A24: • MAYBE_LOCKED — counting consecutive valid packets at the found phase; one invalid packet → back to NOT_LOCKED.
A25: • LOCKED — reached after LVT consecutive valid packets; single-bit CRC errors are corrected, data is output.

Sheet Summary
A1: Verification Progress Summary
A2: All numbers are live formulas over the 'Attribute List' sheet — they update when you change V / X.
A4: Group | B4: Test Cases | C4: Implemented | D4: % Impl. | E4: Checked | F4: % Checked
A5: System assumptions | B5: =COUNTIFS('Attribute List'!$I$6:$I$47,"SYS",'Attribute List'!$E$6:$E$47,"<>") | C5: =COUNTIFS('Attribute List'!$I$6:$I$47,"SYS",'Attribute List'!$G$6:$G$47,"V") | D5: =IF(B5=0,0,C5/B5) | E5: =COUNTIFS('Attribute List'!$I$6:$I$47,"SYS",'Attribute List'!$H$6:$H$47,"V") | F5: =IF(B5=0,0,E5/B5)
A6: Lock | B6: =COUNTIFS('Attribute List'!$I$6:$I$47,"LCK",'Attribute List'!$E$6:$E$47,"<>") | C6: =COUNTIFS('Attribute List'!$I$6:$I$47,"LCK",'Attribute List'!$G$6:$G$47,"V") | D6: =IF(B6=0,0,C6/B6) | E6: =COUNTIFS('Attribute List'!$I$6:$I$47,"LCK",'Attribute List'!$H$6:$H$47,"V") | F6: =IF(B6=0,0,E6/B6)
A7: Message size | B7: =COUNTIFS('Attribute List'!$I$6:$I$47,"SIZ",'Attribute List'!$E$6:$E$47,"<>") | C7: =COUNTIFS('Attribute List'!$I$6:$I$47,"SIZ",'Attribute List'!$G$6:$G$47,"V") | D7: =IF(B7=0,0,C7/B7) | E7: =COUNTIFS('Attribute List'!$I$6:$I$47,"SIZ",'Attribute List'!$H$6:$H$47,"V") | F7: =IF(B7=0,0,E7/B7)
A8: Length + CRC errors | B8: =COUNTIFS('Attribute List'!$I$6:$I$47,"LEN",'Attribute List'!$E$6:$E$47,"<>") | C8: =COUNTIFS('Attribute List'!$I$6:$I$47,"LEN",'Attribute List'!$G$6:$G$47,"V") | D8: =IF(B8=0,0,C8/B8) | E8: =COUNTIFS('Attribute List'!$I$6:$I$47,"LEN",'Attribute List'!$H$6:$H$47,"V") | F8: =IF(B8=0,0,E8/B8)
A9: Control + CRC errors | B9: =COUNTIFS('Attribute List'!$I$6:$I$47,"CTL",'Attribute List'!$E$6:$E$47,"<>") | C9: =COUNTIFS('Attribute List'!$I$6:$I$47,"CTL",'Attribute List'!$G$6:$G$47,"V") | D9: =IF(B9=0,0,C9/B9) | E9: =COUNTIFS('Attribute List'!$I$6:$I$47,"CTL",'Attribute List'!$H$6:$H$47,"V") | F9: =IF(B9=0,0,E9/B9)
A10: Output control | B10: =COUNTIFS('Attribute List'!$I$6:$I$47,"OCT",'Attribute List'!$E$6:$E$47,"<>") | C10: =COUNTIFS('Attribute List'!$I$6:$I$47,"OCT",'Attribute List'!$G$6:$G$47,"V") | D10: =IF(B10=0,0,C10/B10) | E10: =COUNTIFS('Attribute List'!$I$6:$I$47,"OCT",'Attribute List'!$H$6:$H$47,"V") | F10: =IF(B10=0,0,E10/B10)
A11: Phase | B11: =COUNTIFS('Attribute List'!$I$6:$I$47,"PHS",'Attribute List'!$E$6:$E$47,"<>") | C11: =COUNTIFS('Attribute List'!$I$6:$I$47,"PHS",'Attribute List'!$G$6:$G$47,"V") | D11: =IF(B11=0,0,C11/B11) | E11: =COUNTIFS('Attribute List'!$I$6:$I$47,"PHS",'Attribute List'!$H$6:$H$47,"V") | F11: =IF(B11=0,0,E11/B11)
A12: Parity | B12: =COUNTIFS('Attribute List'!$I$6:$I$47,"PAR",'Attribute List'!$E$6:$E$47,"<>") | C12: =COUNTIFS('Attribute List'!$I$6:$I$47,"PAR",'Attribute List'!$G$6:$G$47,"V") | D12: =IF(B12=0,0,C12/B12) | E12: =COUNTIFS('Attribute List'!$I$6:$I$47,"PAR",'Attribute List'!$H$6:$H$47,"V") | F12: =IF(B12=0,0,E12/B12)
A13: Random input valid | B13: =COUNTIFS('Attribute List'!$I$6:$I$47,"VLD",'Attribute List'!$E$6:$E$47,"<>") | C13: =COUNTIFS('Attribute List'!$I$6:$I$47,"VLD",'Attribute List'!$G$6:$G$47,"V") | D13: =IF(B13=0,0,C13/B13) | E13: =COUNTIFS('Attribute List'!$I$6:$I$47,"VLD",'Attribute List'!$H$6:$H$47,"V") | F13: =IF(B13=0,0,E13/B13)
A14: TOTAL | B14: =SUM(B5:B13) | C14: =SUM(C5:C13) | D14: =IF(B14=0,0,C14/B14) | E14: =SUM(E5:E13) | F14: =IF(B14=0,0,E14/B14)

Sheet Attribute List
A1: RX Block — Attribute List (AL)
A2: Functional attributes of the RX module, derived from the block specification. This list is written before the Verification Plan — the VP and the verification environment are built from it.
E3: PRIORITY | F3: High | G3: Medium | H3: Low
E4: STATUS (Implemented / Checked) | G4: V • Done | H4: X • Not done
A5: ID | B5: Group | C5: Attribute (The module shall … when …) | D5: Notes / Assumptions | E5: Test Case (standard & corner cases) | F5: Priority | G5: Implemented (V / X) | H5: Checked (V / X)
A6: SYSTEM — Assumptions (the module cannot work correctly without these)
A7: SYS-01 | B7: System assumptions | C7: Data payload length is always a multiple of 4 bytes. | D7: Parity is a 32-bit word and the output bus is 32 bits wide. | E7: Assumption — not stimulated | F7: High | G7: X | H7: X | I7: SYS
A8: SYS-02 | B8: System assumptions | C8: Once the module is LOCKED it never drops out of lock. | D8: After lock, at most ONE bit error can occur in LENGTH + LENGTH_CRC; 2+ errors after lock are outside the spec. | E8: Assumption — not stimulated | F8: High | G8: X | H8: X | I8: SYS
A9: SYS-03 | B9: System assumptions | C9: The Lock Valid Threshold (LVT) is configured at the start of simulation and never changes. | D9: Legal range: 2 ≤ LVT ≤ 12. LVT input is 16 bits wide. | E9: Assumption — not stimulated | F9: High | G9: X | H9: X | I9: SYS
A10: SYS-04 | B10: System assumptions | C10: Data payload length is at most 8 KB. | D10: Maximum payload is 8192 bytes; LENGTH field is 16 bits. | E10: Assumption — not stimulated | F10: High | G10: X | H10: X | I10: SYS
A11: LOCK — Packet-boundary acquisition (NOT_LOCKED → MAYBE_LOCKED → LOCKED)
A12: LCK-01 | B12: Lock | C12: The module shall enter LOCKED after receiving LVT consecutive valid packets at the same phase. | D12: LVT is set by an external interface. A packet is valid only if LENGTH + LENGTH_CRC is correct (CRC-16, poly 0x1021, init 0xFFFF). All LVT packets must share the same phase for lock to succeed. No data is output until the module is LOCKED. | E12: Send MORE than LVT consecutive valid packets | F12: High | G12: X | H12: X | I12: LCK
E13: Send EXACTLY LVT consecutive valid packets | F13: High | G13: X | H13: X | I13: LCK
E14: Send LVT-1 valid packets, then an invalid packet (drop MAYBE → NOT_LOCKED), then valid packets again | F14: Medium | G14: X | H14: X | I14: LCK
E15: Send 1…LVT-2 valid packets, then an invalid packet (early drop), then valid packets again | F15: Medium | G15: X | H15: X | I15: LCK
E16: Send LVT-a valid packets at one phase, then a valid packet at a LATER phase, then valid packets again (a ≥ 1) | F16: Low | G16: X | H16: X | I16: LCK
E17: Send LVT-a valid packets at one phase, then a valid packet at an EARLIER phase, then valid packets again (a ≥ 1) | F17: Low | G17: X | H17: X | I17: LCK
E18: Lock using a single packet of non-minimal length | F18: Medium | G18: X | H18: X | I18: LCK
A19: LCK-02 | B19: Lock | C19: The module shall lock correctly for every legal LVT value. | D19: Legal range 2…12. Minimum, typical (7) and maximum are the corner values. | E19: LVT = 2 (minimum) | F19: High | G19: X | H19: X | I19: LCK
E20: LVT = 7 (typical) | F20: High | G20: X | H20: X | I20: LCK
E21: LVT = 12 (maximum) | F21: High | G21: X | H21: X | I21: LCK
E22: LVT = every other value in 3…11 | F22: Low | G22: X | H22: X | I22: LCK
A23: DATA PATH — Packet parsing and output
A24: SIZ-01 | B24: Message size | C24: The module shall receive and output packets of any legal payload length. | D24: Length range 4 B (minimum) … 4096 B (typical) … 8192 B (maximum). | E24: Packet of minimum size — 4 B (empty payload) | F24: High | G24: X | H24: X | I24: SIZ
E25: Packet of optimal size — 4 KB (4096 B) | F25: High | G25: X | H25: X | I25: SIZ
E26: Packet of maximum size — 8 KB (8192 B) | F26: High | G26: X | H26: X | I26: SIZ
E27: Packets in every 1 KB range between min and max | F27: Medium | G27: X | H27: X | I27: SIZ
E28: Real-traffic pattern: several 4 KB packets → a remainder packet → empty packets, repeated many times | F28: Medium | G28: X | H28: X | I28: SIZ
A29: LEN-01 | B29: Length + CRC errors | C29: The module shall correct a packet that arrives with a single-bit error in LENGTH / LENGTH_CRC. | D29: At most one error in LENGTH + LENGTH_CRC is allowed after lock. Correction only happens after the module is LOCKED. Before lock, 2+ errors make the packet invalid (back to NOT_LOCKED). Should be combined with CTL-01 (length errors together with control errors). | E29: Valid packet (0 errors) | F29: High | G29: X | H29: X | I29: LEN
E30: Packet with exactly 1 bit error | F30: High | G30: X | H30: X | I30: LEN
E31: Packet with 2+ errors while MAYBE_LOCKED (invalid → drop to NOT_LOCKED) | F31: Medium | G31: X | H31: X | I31: LEN
A32: CTL-01 | B32: Control + CRC errors | C32: The module shall correct a packet that arrives with a single-bit error in CONTROL / CONTROL_CRC. | D32: At most one error in CONTROL + CONTROL_CRC. Correction only happens after the module is LOCKED. CRC-16, poly 0x8005, init 0x0000. Combine with LEN-01. | E32: Valid packet (0 errors) | F32: High | G32: X | H32: X | I32: CTL
E33: Packet with exactly 1 bit error | F33: High | G33: X | H33: X | I33: CTL
A34: OCT-01 | B34: Output control | C34: The module shall output the CONTROL word only when its (corrected) value is non-zero. | D34: A CONTROL value of 0 is never output. CONTROL is 16 bits. | E34: CONTROL = 0 → not output | F34: High | G34: X | H34: X | I34: OCT
E35: CONTROL ≠ 0 → output | F35: High | G35: X | H35: X | I35: OCT
E36: Send CONTROL = 1 with a bit error that makes it look like 0 → must still be output after correction | F36: Medium | G36: X | H36: X | I36: OCT
E37: Send CONTROL = 0 with a bit error that makes it look like 1 → must NOT be output after correction | F37: Medium | G37: X | H37: X | I37: OCT
A38: PHS-01 | B38: Phase | C38: The module shall determine the packet phase from the traffic received before lock and keep it once LOCKED. | D38: Input is a 4-bit nibble bus, so packet boundaries can start at nibble offset 0-3 (phase N ≡ N+4). The offset depends on where the traffic starts relative to packet boundaries. | E38: Phase 0 | F38: High | G38: X | H38: X | I38: PHS
E39: Phase 1 | F39: High | G39: X | H39: X | I39: PHS
E40: Phase 2 | F40: High | G40: X | H40: X | I40: PHS
...
